[2022-07-29 19:51:08,327] {taskinstance.py:1179} INFO - Dependencies all met for <TaskInstance: weather_dag.weather manual__2022-07-29T19:51:06.320605+00:00 [queued]>
[2022-07-29 19:51:08,392] {taskinstance.py:1179} INFO - Dependencies all met for <TaskInstance: weather_dag.weather manual__2022-07-29T19:51:06.320605+00:00 [queued]>
[2022-07-29 19:51:08,393] {taskinstance.py:1376} INFO - 
--------------------------------------------------------------------------------
[2022-07-29 19:51:08,395] {taskinstance.py:1377} INFO - Starting attempt 1 of 2
[2022-07-29 19:51:08,396] {taskinstance.py:1378} INFO - 
--------------------------------------------------------------------------------
[2022-07-29 19:51:08,490] {taskinstance.py:1397} INFO - Executing <Task(PythonOperator): weather> on 2022-07-29 19:51:06.320605+00:00
[2022-07-29 19:51:08,525] {standard_task_runner.py:52} INFO - Started process 415 to run task
[2022-07-29 19:51:08,547] {standard_task_runner.py:79} INFO - Running: ['***', 'tasks', 'run', 'weather_dag', 'weather', 'manual__2022-07-29T19:51:06.320605+00:00', '--job-id', '4', '--raw', '--subdir', 'DAGS_FOLDER/weather_dag.py', '--cfg-path', '/tmp/tmp1bct2h51', '--error-file', '/tmp/tmplk_2_hpd']
[2022-07-29 19:51:08,563] {standard_task_runner.py:80} INFO - Job 4: Subtask weather
[2022-07-29 19:51:08,942] {task_command.py:371} INFO - Running <TaskInstance: weather_dag.weather manual__2022-07-29T19:51:06.320605+00:00 [running]> on host 43173a86041a
[2022-07-29 19:51:09,114] {taskinstance.py:1589} INFO - Exporting the following env vars:
AIRFLOW_CTX_DAG_EMAIL=***@example.com
AIRFLOW_CTX_DAG_OWNER=***
AIRFLOW_CTX_DAG_ID=weather_dag
AIRFLOW_CTX_TASK_ID=weather
AIRFLOW_CTX_EXECUTION_DATE=2022-07-29T19:51:06.320605+00:00
AIRFLOW_CTX_TRY_NUMBER=1
AIRFLOW_CTX_DAG_RUN_ID=manual__2022-07-29T19:51:06.320605+00:00
[2022-07-29 19:51:09,119] {taskinstance.py:1909} ERROR - Task failed with exception
Traceback (most recent call last):
  File "/home/airflow/.local/lib/python3.8/site-packages/airflow/operators/python.py", line 171, in execute
    return_value = self.execute_callable()
  File "/home/airflow/.local/lib/python3.8/site-packages/airflow/operators/python.py", line 189, in execute_callable
    return self.python_callable(*self.op_args, **self.op_kwargs)
  File "/opt/airflow/dags/weather_dag.py", line 20, in weather_etl
    from scripts.etl import run_weather_etl
ModuleNotFoundError: No module named 'scripts.etl'
[2022-07-29 19:51:09,142] {taskinstance.py:1415} INFO - Marking task as UP_FOR_RETRY. dag_id=weather_dag, task_id=weather, execution_date=20220729T195106, start_date=20220729T195108, end_date=20220729T195109
[2022-07-29 19:51:09,166] {standard_task_runner.py:92} ERROR - Failed to execute job 4 for task weather (No module named 'scripts.etl'; 415)
[2022-07-29 19:51:09,217] {local_task_job.py:156} INFO - Task exited with return code 1
[2022-07-29 19:51:09,322] {local_task_job.py:273} INFO - 0 downstream tasks scheduled from follow-on schedule check
