[2022-08-01 18:30:39,360] {taskinstance.py:1179} INFO - Dependencies all met for <TaskInstance: weather_dag.weather manual__2022-08-01T18:30:36.217449+00:00 [queued]>
[2022-08-01 18:30:39,393] {taskinstance.py:1179} INFO - Dependencies all met for <TaskInstance: weather_dag.weather manual__2022-08-01T18:30:36.217449+00:00 [queued]>
[2022-08-01 18:30:39,397] {taskinstance.py:1376} INFO - 
--------------------------------------------------------------------------------
[2022-08-01 18:30:39,403] {taskinstance.py:1377} INFO - Starting attempt 1 of 2
[2022-08-01 18:30:39,412] {taskinstance.py:1378} INFO - 
--------------------------------------------------------------------------------
[2022-08-01 18:30:39,465] {taskinstance.py:1397} INFO - Executing <Task(PythonOperator): weather> on 2022-08-01 18:30:36.217449+00:00
[2022-08-01 18:30:39,474] {standard_task_runner.py:52} INFO - Started process 289 to run task
[2022-08-01 18:30:39,488] {standard_task_runner.py:79} INFO - Running: ['***', 'tasks', 'run', 'weather_dag', 'weather', 'manual__2022-08-01T18:30:36.217449+00:00', '--job-id', '74', '--raw', '--subdir', 'DAGS_FOLDER/weather_dag.py', '--cfg-path', '/tmp/tmpes6b3k7o', '--error-file', '/tmp/tmps_woeygm']
[2022-08-01 18:30:39,499] {standard_task_runner.py:80} INFO - Job 74: Subtask weather
[2022-08-01 18:30:39,620] {task_command.py:371} INFO - Running <TaskInstance: weather_dag.weather manual__2022-08-01T18:30:36.217449+00:00 [running]> on host 609638d3e31f
[2022-08-01 18:30:39,750] {taskinstance.py:1589} INFO - Exporting the following env vars:
AIRFLOW_CTX_DAG_EMAIL=***@example.com
AIRFLOW_CTX_DAG_OWNER=***
AIRFLOW_CTX_DAG_ID=weather_dag
AIRFLOW_CTX_TASK_ID=weather
AIRFLOW_CTX_EXECUTION_DATE=2022-08-01T18:30:36.217449+00:00
AIRFLOW_CTX_TRY_NUMBER=1
AIRFLOW_CTX_DAG_RUN_ID=manual__2022-08-01T18:30:36.217449+00:00
[2022-08-01 18:30:39,756] {logging_mixin.py:115} INFO - ETL Pipeline
[2022-08-01 18:30:39,758] {logging_mixin.py:115} INFO - Extraction stage started...
[2022-08-01 18:30:39,760] {logging_mixin.py:115} INFO - url done
[2022-08-01 18:30:39,951] {logging_mixin.py:115} INFO - Transform stage started...
[2022-08-01 18:30:39,973] {logging_mixin.py:115} INFO - Data is valid, proceed to load stage.
[2022-08-01 18:30:39,975] {logging_mixin.py:115} INFO - Load stage started...
[2022-08-01 18:30:39,983] {logging_mixin.py:115} INFO - Database open successfully
[2022-08-01 18:30:40,004] {taskinstance.py:1909} ERROR - Task failed with exception
Traceback (most recent call last):
  File "/home/airflow/.local/lib/python3.8/site-packages/sqlalchemy/engine/base.py", line 1782, in _execute_context
    self.dialect.do_executemany(
  File "/home/airflow/.local/lib/python3.8/site-packages/sqlalchemy/engine/default.py", line 716, in do_executemany
    cursor.executemany(statement, parameters)
sqlite3.IntegrityError: UNIQUE constraint failed: weather.daytime

The above exception was the direct cause of the following exception:

Traceback (most recent call last):
  File "/home/airflow/.local/lib/python3.8/site-packages/airflow/operators/python.py", line 171, in execute
    return_value = self.execute_callable()
  File "/home/airflow/.local/lib/python3.8/site-packages/airflow/operators/python.py", line 189, in execute_callable
    return self.python_callable(*self.op_args, **self.op_kwargs)
  File "/opt/airflow/dags/script/WeatherETL.py", line 170, in run_weather_etl
    weather_df.to_sql("weather", engine, index=False, if_exists='append')
  File "/home/airflow/.local/lib/python3.8/site-packages/pandas/core/generic.py", line 2951, in to_sql
    return sql.to_sql(
  File "/home/airflow/.local/lib/python3.8/site-packages/pandas/io/sql.py", line 697, in to_sql
    return pandas_sql.to_sql(
  File "/home/airflow/.local/lib/python3.8/site-packages/pandas/io/sql.py", line 1739, in to_sql
    total_inserted = sql_engine.insert_records(
  File "/home/airflow/.local/lib/python3.8/site-packages/pandas/io/sql.py", line 1332, in insert_records
    raise err
  File "/home/airflow/.local/lib/python3.8/site-packages/pandas/io/sql.py", line 1322, in insert_records
    return table.insert(chunksize=chunksize, method=method)
  File "/home/airflow/.local/lib/python3.8/site-packages/pandas/io/sql.py", line 950, in insert
    num_inserted = exec_insert(conn, keys, chunk_iter)
  File "/home/airflow/.local/lib/python3.8/site-packages/pandas/io/sql.py", line 857, in _execute_insert
    result = conn.execute(self.table.insert(), data)
  File "/home/airflow/.local/lib/python3.8/site-packages/sqlalchemy/engine/base.py", line 1289, in execute
    return meth(self, multiparams, params, _EMPTY_EXECUTION_OPTS)
  File "/home/airflow/.local/lib/python3.8/site-packages/sqlalchemy/sql/elements.py", line 325, in _execute_on_connection
    return connection._execute_clauseelement(
  File "/home/airflow/.local/lib/python3.8/site-packages/sqlalchemy/engine/base.py", line 1481, in _execute_clauseelement
    ret = self._execute_context(
  File "/home/airflow/.local/lib/python3.8/site-packages/sqlalchemy/engine/base.py", line 1845, in _execute_context
    self._handle_dbapi_exception(
  File "/home/airflow/.local/lib/python3.8/site-packages/sqlalchemy/engine/base.py", line 2026, in _handle_dbapi_exception
    util.raise_(
  File "/home/airflow/.local/lib/python3.8/site-packages/sqlalchemy/util/compat.py", line 207, in raise_
    raise exception
  File "/home/airflow/.local/lib/python3.8/site-packages/sqlalchemy/engine/base.py", line 1782, in _execute_context
    self.dialect.do_executemany(
  File "/home/airflow/.local/lib/python3.8/site-packages/sqlalchemy/engine/default.py", line 716, in do_executemany
    cursor.executemany(statement, parameters)
sqlalchemy.exc.IntegrityError: (sqlite3.IntegrityError) UNIQUE constraint failed: weather.daytime
[SQL: INSERT INTO weather ("Daytime", "Day", "Hours", "Temperature", "isDay", "Humidity") VALUES (?, ?, ?, ?, ?, ?)]
[parameters: (('2022-07-31 00:00', '2022-07-31', '00:00', 77.7, 0, 89), ('2022-07-31 01:00', '2022-07-31', '01:00', 77.6, 0, 88), ('2022-07-31 02:00', '2022-07-31', '02:00', 77.5, 0, 88), ('2022-07-31 03:00', '2022-07-31', '03:00', 77.4, 0, 88), ('2022-07-31 04:00', '2022-07-31', '04:00', 77.4, 0, 88), ('2022-07-31 05:00', '2022-07-31', '05:00', 77.4, 0, 87), ('2022-07-31 06:00', '2022-07-31', '06:00', 77.4, 0, 87), ('2022-07-31 07:00', '2022-07-31', '07:00', 79.2, 1, 83)  ... displaying 10 of 24 total bound parameter sets ...  ('2022-07-31 22:00', '2022-07-31', '22:00', 78.9, 0, 81), ('2022-07-31 23:00', '2022-07-31', '23:00', 78.4, 0, 82))]
(Background on this error at: https://sqlalche.me/e/14/gkpj)
[2022-08-01 18:30:40,056] {taskinstance.py:1415} INFO - Marking task as UP_FOR_RETRY. dag_id=weather_dag, task_id=weather, execution_date=20220801T183036, start_date=20220801T183039, end_date=20220801T183040
[2022-08-01 18:30:40,099] {standard_task_runner.py:92} ERROR - Failed to execute job 74 for task weather ((sqlite3.IntegrityError) UNIQUE constraint failed: weather.daytime
[SQL: INSERT INTO weather ("Daytime", "Day", "Hours", "Temperature", "isDay", "Humidity") VALUES (?, ?, ?, ?, ?, ?)]
[parameters: (('2022-07-31 00:00', '2022-07-31', '00:00', 77.7, 0, 89), ('2022-07-31 01:00', '2022-07-31', '01:00', 77.6, 0, 88), ('2022-07-31 02:00', '2022-07-31', '02:00', 77.5, 0, 88), ('2022-07-31 03:00', '2022-07-31', '03:00', 77.4, 0, 88), ('2022-07-31 04:00', '2022-07-31', '04:00', 77.4, 0, 88), ('2022-07-31 05:00', '2022-07-31', '05:00', 77.4, 0, 87), ('2022-07-31 06:00', '2022-07-31', '06:00', 77.4, 0, 87), ('2022-07-31 07:00', '2022-07-31', '07:00', 79.2, 1, 83)  ... displaying 10 of 24 total bound parameter sets ...  ('2022-07-31 22:00', '2022-07-31', '22:00', 78.9, 0, 81), ('2022-07-31 23:00', '2022-07-31', '23:00', 78.4, 0, 82))]
(Background on this error at: https://sqlalche.me/e/14/gkpj); 289)
[2022-08-01 18:30:40,140] {local_task_job.py:156} INFO - Task exited with return code 1
[2022-08-01 18:30:40,241] {local_task_job.py:273} INFO - 0 downstream tasks scheduled from follow-on schedule check
